<?xml version="1.0" encoding="utf-8"?>
<!-- This URDF was automatically created by SolidWorks to URDF Exporter! Originally created by Stephen Brawner (brawner@gmail.com) 
     Commit Version: 1.5.1-0-g916b5db  Build Version: 1.5.7152.31018
     For more information, please see http://wiki.ros.org/sw_urdf_exporter -->
<robot
  name="car_urdf">
  
  <!-- <link name="world"/>
  <joint name="base_joint" type="fixed">
  	<parent link="world"/>
  	<child link="base_link"/>
  	<origin rpy="0 0 0" xyz="0.0 0.0 0.0"/>
	</joint>-->

  <!-- root link, on the ground just below the model origin -->
  <link name="base_footprint">
   <visual>
      <origin xyz="0 0 0" rpy="0 0 0" />
      <geometry>
        <box size="0.001 0.001 0.001" />
      </geometry>
    </visual>

  </link>
  <joint name="base_link_joint" type="fixed">
    <origin xyz="0.0 0.0 0.0" rpy="0 0 0" />
    <parent link="base_footprint"/>
    <child link="base_link" />
  </joint>

  <link
    name="base_link">
    <inertial>
      <origin
        xyz="0.0022297881096239 -0.000937529913435931 0.0375283758051956"
        rpy="0 0 0" />
      <mass
        value="20" />
      <inertia
        ixx="0.00260667894961256"
        ixy="-2.06641366246688E-01"
        ixz="-4.51471929494189E-01"
        iyy="0.00634991698764481"
        iyz="1.79850575748149E-01"
        izz="0.00843754522990492" />
    </inertial>
    <visual>
      <origin
        xyz="0 0 0"
        rpy="0 0 0" />
      <geometry>
        <mesh
          filename="package://car_urdf/meshes/base_link.STL" />
      </geometry>
      <material
        name="">
        <color
          rgba="1 1 1 1" />
      </material>
    </visual>
    <collision>
      <origin
        xyz="0 0 0"
        rpy="0 0 0" />
      <geometry>
        <mesh
          filename="package://car_urdf/meshes/base_link.STL" />
      </geometry>
    </collision>
  </link>
  <link
    name="Rueda_izquierda_del_link">
    <inertial>
      <origin
        xyz="1.72244410720085E-05 -3.08770137943844E-05 -0.0187646103151318"
        rpy="0 0 0" />
      <mass
        value="5" />
      <inertia
        ixx="2.81559000731179E-01"
        ixy="0"
        ixz="0"
        iyy="2.81431703190276E-01"
        iyz="0"
        izz="4.55341024054628E-01" />
    </inertial>
    <visual>
      <origin
        xyz="0 0 0"
        rpy="0 0 0" />
      <geometry>
        <mesh
          filename="package://car_urdf/meshes/Rueda_izquierda_del_link.STL" />
      </geometry>
      <material
        name="">
        <color
          rgba="0.752941176470588 0.752941176470588 0.752941176470588 1" />
      </material>
    </visual>
    <collision>
      <origin
        xyz="0 0 0"
        rpy="0 0 0" />
      <geometry>
        <mesh
          filename="package://car_urdf/meshes/Rueda_izquierda_del_link.STL" />
      </geometry>
    </collision>
  </link>
  <joint
    name="Rueda_izquierda_del_joint"
    type="continuous">
    <origin
      xyz="0.11005 0.1295 0.026733"
      rpy="-1.5708 0 0" />
    <parent
      link="base_link" />
    <child
      link="Rueda_izquierda_del_link" />
    <axis
      xyz="0 0 1" />
    <limit
      effort="100"
      velocity="100" />
    <joint_properties damping="0.0" friction="0.0"/>
  </joint>
  <link
    name="Rueda_derecha_del_link">
    <inertial>
      <origin
        xyz="-2.01928690935771E-05 -3.56300614159852E-05 0.0187939302958306"
        rpy="0 0 0" />
      <mass
        value="5" />
      <inertia
        ixx="2.82629959834746E-01"
        ixy="0"
        ixz="0"
        iyy="2.82506382127236E-01"
        iyz="0"
        izz="4.55976190910373E-01" />
    </inertial>
    <visual>
      <origin
        xyz="0 0 0"
        rpy="0 0 0" />
      <geometry>
        <mesh
          filename="package://car_urdf/meshes/Rueda_derecha_del_link.STL" />
      </geometry>
      <material
        name="">
        <color
          rgba="0.752941176470588 0.752941176470588 0.752941176470588 1" />
      </material>
    </visual>
    <collision>
      <origin
        xyz="0 0 0"
        rpy="0 0 0" />
      <geometry>
        <mesh
          filename="package://car_urdf/meshes/Rueda_derecha_del_link.STL" />
      </geometry>
    </collision>
  </link>
  <joint
    name="Rueda_derecha_del_joint"
    type="continuous">
    <origin
      xyz="0.1104 -0.13066 0.02641"
      rpy="-1.5708 0 0" />
    <parent
      link="base_link" />
    <child
      link="Rueda_derecha_del_link" />
    <axis
      xyz="0 0 1" />
    <limit
      effort="100"
      velocity="100" />
    <joint_properties damping="0.0" friction="0.0"/>
  </joint>
  <link
    name="Rueda_izquierda_tras_link">
    <inertial>
      <origin
        xyz="-1.16739382335779E-05 -3.9255221370698E-05 -0.0187939302958305"
        rpy="0 0 0" />
      <mass
        value="5" />
      <inertia
        ixx="2.82571265705397E-01"
        ixy="0"
        ixz="0"
        iyy="2.82565076256586E-01"
        iyz="0"
        izz="4.55976190910372E-01" />
    </inertial>
    <visual>
      <origin
        xyz="0 0 0"
        rpy="0 0 0" />
      <geometry>
        <mesh
          filename="package://car_urdf/meshes/Rueda_izquierda_tras_link.STL" />
      </geometry>
      <material
        name="">
        <color
          rgba="0.752941176470588 0.752941176470588 0.752941176470588 1" />
      </material>
    </visual>
    <collision>
      <origin
        xyz="0 0 0"
        rpy="0 0 0" />
      <geometry>
        <mesh
          filename="package://car_urdf/meshes/Rueda_izquierda_tras_link.STL" />
      </geometry>
    </collision>
  </link>
  <joint
    name="Rueda_izquierda_tras_joint"
    type="continuous">
    <origin
      xyz="-0.11021 0.13066 0.026148"
      rpy="-1.5708 0 0" />
    <parent
      link="base_link" />
    <child
      link="Rueda_izquierda_tras_link" />
    <axis
      xyz="0 0 1" />
    <limit
      effort="100"
      velocity="100" />
    <joint_properties damping="0.0" friction="0.0"/>
  </joint>
  <link
    name="Rueda_derecha_tras_link">
    <inertial>
      <origin
        xyz="-1.26738293365902E-05 -3.30067478108674E-05 0.0187646103151317"
        rpy="0 0 0" />
      <mass
        value="5" />
      <inertia
        ixx="2.81556321484253E-01"
        ixy="0"
        ixz="0"
        iyy="2.81434382437204E-01"
        iyz="0"
        izz="4.5534102405463E-01" />
    </inertial>
    <visual>
      <origin
        xyz="0 0 0"
        rpy="0 0 0" />
      <geometry>
        <mesh
          filename="package://car_urdf/meshes/Rueda_derecha_tras_link.STL" />
      </geometry>
      <material
        name="">
        <color
          rgba="0.752941176470588 0.752941176470588 0.752941176470588 1" />
      </material>
    </visual>
    <collision>
      <origin
        xyz="0 0 0"
        rpy="0 0 0" />
      <geometry>
        <mesh
          filename="package://car_urdf/meshes/Rueda_derecha_tras_link.STL" />
      </geometry>
    </collision>
  </link>
  <joint
    name="Rueda_derecha_tras_joint"
    type="continuous">
    <origin
      xyz="-0.11002 -0.1295 0.026739"
      rpy="-1.5708 0 0" />
    <parent
      link="base_link" />
    <child
      link="Rueda_derecha_tras_link" />
    <axis
      xyz="0 0 1" />
    <limit
      effort="100"
      velocity="100" />
    <joint_properties damping="0.0" friction="0.0"/>
  </joint>
  <link
    name="Waist">
    <inertial>
      <origin
        xyz="-0.00643461174884599 0.00137211572604215 0.0172891660034206"
        rpy="0 0 0" />
      <mass
        value="4" />
      <inertia
        ixx="5.81345017333013E-01"
        ixy="0"
        ixz="0"
        iyy="4.50193669493472E-01"
        iyz="0"
        izz="5.46761452959707E-01" />
    </inertial>
    <visual>
      <origin
        xyz="0 0 0"
        rpy="0 0 0" />
      <geometry>
        <mesh
          filename="package://car_urdf/meshes/Waist.STL" />
      </geometry>
      <material
        name="">
        <color
          rgba="0.749019607843137 0.749019607843137 0.749019607843137 1" />
      </material>
    </visual>
    <collision>
      <origin
        xyz="0 0 0"
        rpy="0 0 0" />
      <geometry>
        <mesh
          filename="package://car_urdf/meshes/Waist.STL" />
      </geometry>
    </collision>
  </link>
  <joint
    name="Waist_joint"
    type="revolute">
    <origin
      xyz="0.060849 0 0.08987"
      rpy="0 0 -1.5708" />
    <parent
      link="base_link" />
    <child
      link="Waist" />
    <axis
      xyz="0 0 1" />
    <limit
      lower="-3.1"
      upper="3.1"
      effort="2"
      velocity="2" />
  </joint>
  <link
    name="Shoulder">
    <inertial>
      <origin
        xyz="0.00139575313800894 0.0591884192827652 0.00178931205327423"
        rpy="0 0 0" />
      <mass
        value="4" />
      <inertia
        ixx="0.000106965780568813"
        ixy="0"
        ixz="0"
        iyy="9.15502968245258E-01"
        iyz="0"
        izz="0.000111828463740695" />
    </inertial>
    <visual>
      <origin
        xyz="0 0 0"
        rpy="0 0 0" />
      <geometry>
        <mesh
          filename="package://car_urdf/meshes/Shoulder.STL" />
      </geometry>
      <material
        name="">
        <color
          rgba="0.749019607843137 0.749019607843137 0.749019607843137 1" />
      </material>
    </visual>
    <collision>
      <origin
        xyz="0 0 0"
        rpy="0 0 0" />
      <geometry>
        <mesh
          filename="package://car_urdf/meshes/Shoulder.STL" />
      </geometry>
    </collision>
  </link>
  <joint
    name="Shoulder_joint"
    type="revolute">
    <origin
      xyz="0.002 0.013919 0.040276"
      rpy="1.5708 0 1.5708" />
    <parent
      link="Waist" />
    <child
      link="Shoulder" />
    <axis
      xyz="0 0 1" />
    <limit
      lower="-1.6"
      upper="1.8"
      effort="2"
      velocity="2" />
  </joint>
  <link
    name="Elbow">
    <inertial>
      <origin
        xyz="0.0392853132336417 -2.78813481829343E-05 0.00540885828941906"
        rpy="0 0 0" />
      <mass
        value="2" />
      <inertia
        ixx="9.28666202376571E-01"
        ixy="0"
        ixz="0"
        iyy="5.46008100377437E-01"
        iyz="0"
        izz="5.81488341772465E-01" />
    </inertial>
    <visual>
      <origin
        xyz="0 0 0"
        rpy="0 0 0" />
      <geometry>
        <mesh
          filename="package://car_urdf/meshes/Elbow.STL" />
      </geometry>
      <material
        name="">
        <color
          rgba="0.749019607843137 0.749019607843137 0.749019607843137 1" />
      </material>
    </visual>
    <collision>
      <origin
        xyz="0 0 0"
        rpy="0 0 0" />
      <geometry>
        <mesh
          filename="package://car_urdf/meshes/Elbow.STL" />
      </geometry>
    </collision>
  </link>
  <joint
    name="Elbow_joint"
    type="revolute">
    <origin
      xyz="0.0028289 0.11997 -0.008"
      rpy="3.1416 0 0" />
    <parent
      link="Shoulder" />
    <child
      link="Elbow" />
    <axis
      xyz="0 0 1" />
    <limit
      lower="-3.8"
      upper="0.9"
      effort="2"
      velocity="2" />
  </joint>
  <link
    name="Wrist_Roll">
    <inertial>
      <origin
        xyz="0.00497214222074152 0.00533442843610391 0.0178414446624296"
        rpy="0 0 0" />
      <mass
        value="2" />
      <inertia
        ixx="3.91251960534152E-01"
        ixy="0"
        ixz="0"
        iyy="5.02240887777995E-01"
        iyz="0"
        izz="2.6123880151547E-01" />
    </inertial>
    <visual>
      <origin
        xyz="0 0 0"
        rpy="0 0 0" />
      <geometry>
        <mesh
          filename="package://car_urdf/meshes/Wrist_Roll.STL" />
      </geometry>
      <material
        name="">
        <color
          rgba="0.749019607843137 0.749019607843137 0.749019607843137 1" />
      </material>
    </visual>
    <collision>
      <origin
        xyz="0 0 0"
        rpy="0 0 0" />
      <geometry>
        <mesh
          filename="package://car_urdf/meshes/Wrist_Roll.STL" />
      </geometry>
    </collision>
  </link>
  <joint
    name="Wrist_Roll_joint"
    type="revolute">
    <origin
      xyz="0.08975 0.0053 0.0055"
      rpy="-1.5708 0 -1.5708" />
    <parent
      link="Elbow" />
    <child
      link="Wrist_Roll" />
    <axis
      xyz="0 0 1" />
    <limit
      lower="-3.1"
      upper="3.1"
      effort="2"
      velocity="2" />
  </joint>
  <link
    name="Wrist_pitch">
    <inertial>
      <origin
        xyz="0.00584372490457619 0.0235511325024931 0.00189540333933991"
        rpy="0 0 0" />
      <mass
        value="1" />
      <inertia
        ixx="8.10583599818438E-01"
        ixy="0"
        ixz="0"
        iyy="2.56045828198375E-01"
        iyz="0"
        izz="7.25737022876247E-01" />
    </inertial>
    <visual>
      <origin
        xyz="0 0 0"
        rpy="0 0 0" />
      <geometry>
        <mesh
          filename="package://car_urdf/meshes/Wrist_pitch.STL" />
      </geometry>
      <material
        name="">
        <color
          rgba="0.749019607843137 0.749019607843137 0.749019607843137 1" />
      </material>
    </visual>
    <collision>
      <origin
        xyz="0 0 0"
        rpy="0 0 0" />
      <geometry>
        <mesh
          filename="package://car_urdf/meshes/Wrist_pitch.STL" />
      </geometry>
    </collision>
  </link>
  <joint
    name="Wrist_pitch_joint"
    type="revolute">
    <origin
      xyz="0.0048045 0.014068 0.028"
      rpy="1.5708 0 0" />
    <parent
      link="Wrist_Roll" />
    <child
      link="Wrist_pitch" />
    <axis
      xyz="0 0 1" />
    <limit
      lower="-2.7"
      upper="1.5"
      effort="2"
      velocity="2" />
  </joint>
  <link
    name="Left_gear">
    <inertial>
      <origin
        xyz="9.84573017270562E-05 0.00569626374754378 -0.00200156536681623"
        rpy="0 0 0" />
      <mass
        value="0.4" />
      <inertia
        ixx="3.59754543872306E-01"
        ixy="0"
        ixz="0"
        iyy="9.32670641947356E-01"
        iyz="0"
        izz="4.4614578747537E-01" />
    </inertial>
    <visual>
      <origin
        xyz="0 0 0"
        rpy="0 0 0" />
      <geometry>
        <mesh
          filename="package://car_urdf/meshes/Left_gear.STL" />
      </geometry>
      <material
        name="">
        <color
          rgba="0.749019607843137 0.749019607843137 0.749019607843137 1" />
      </material>
    </visual>
    <collision>
      <origin
        xyz="0 0 0"
        rpy="0 0 0" />
      <geometry>
        <mesh
          filename="package://car_urdf/meshes/Left_gear.STL" />
      </geometry>
    </collision>
  </link>
  <joint
    name="Left_gear_joint"
    type="revolute">
    <origin
      xyz="0.018248 0.038 0.017648"
      rpy="0 1.5708 0" />
    <parent
      link="Wrist_pitch" />
    <child
      link="Left_gear" />
    <axis
      xyz="0 0 1" />
    <limit
      lower="0.0"
      upper="1.7"
      effort="0.1"
      velocity="1" />
  </joint>
  <link
    name="Left_arm">
    <inertial>
      <origin
        xyz="0.00630542048779029 0.0264992665789138 -0.00833860452056118"
        rpy="0 0 0" />
      <mass
        value="0.5" />
      <inertia
        ixx="1.64746746495668E-01"
        ixy="0"
        ixz="0"
        iyy="1.31449992734637E-01"
        iyz="0"
        izz="1.71389793077299E-01" />
    </inertial>
    <visual>
      <origin
        xyz="0 0 0"
        rpy="0 0 0" />
      <geometry>
        <mesh
          filename="package://car_urdf/meshes/Left_arm.STL" />
      </geometry>
      <material
        name="">
        <color
          rgba="0.749019607843137 0.749019607843137 0.749019607843137 1" />
      </material>
    </visual>
    <collision>
      <origin
        xyz="0 0 0"
        rpy="0 0 0" />
      <geometry>
        <mesh
          filename="package://car_urdf/meshes/Left_arm.STL" />
      </geometry>
    </collision>
  </link>
  <joint
    name="Left_arm_joint"
    type="revolute">
    <origin
      xyz="-0.0025844 0.030641 3.5997E-05"
      rpy="0 0 0" />
    <parent
      link="Left_gear" />
    <child
      link="Left_arm" />
    <axis
      xyz="0 0 1" />
    <limit
      lower="-1.7"
      upper="0.0"
      effort="0.1"
      velocity="1" />
      <!--<mimic
      joint="Left_gear_joint"
      multiplier="-1"
      offset="0" />-->
  </joint>
  <link
    name="Rigth_gear">
    <inertial>
      <origin
        xyz="-0.000446050700060208 0.00559552490810192 -0.0019939810406126"
        rpy="0 0 0" />
      <mass
        value="0.4" />
      <inertia
        ixx="3.63349411456806E-01"
        ixy="0"
        ixz="0"
        iyy="9.0950833728359E-01"
        iyz="0"
        izz="4.4722339189378E-01" />
    </inertial>
    <visual>
      <origin
        xyz="0 0 0"
        rpy="0 0 0" />
      <geometry>
        <mesh
          filename="package://car_urdf/meshes/Rigth_gear.STL" />
      </geometry>
      <material
        name="">
        <color
          rgba="0.749019607843137 0.749019607843137 0.749019607843137 1" />
      </material>
    </visual>
    <collision>
      <origin
        xyz="0 0 0"
        rpy="0 0 0" />
      <geometry>
        <mesh
          filename="package://car_urdf/meshes/Rigth_gear.STL" />
      </geometry>
    </collision>
  </link>
  <joint
    name="Rigth_gear_joint"
    type="revolute">
    <origin
      xyz="0.0178729072833145 0.0379999959318534 -0.00924982705729846"
      rpy="0 1.5707963267949 0" />
    <parent
      link="Wrist_pitch" />
    <child
      link="Rigth_gear" />
    <axis
      xyz="0.0139274180837466 0 0.999903008809115" />
    <limit
      lower="-1.7"
      upper="0.0"
      effort="0.1"
      velocity="1" />
    <!--<mimic
      joint="Left_gear_joint"
      multiplier="-1"
      offset="0" />-->
  </joint>
  <link
    name="Right_arm">
    <inertial>
      <origin
        xyz="-0.00642854067390169 0.0265248882577793 -0.00816128121125931"
        rpy="0 0 0" />
      <mass
        value="0.7" />
      <inertia
        ixx="1.64746746495668E-01"
        ixy="0"
        ixz="0"
        iyy="1.31449992734637E-01"
        iyz="0"
        izz="1.71389793077299E-01" />
    </inertial>
    <visual>
      <origin
        xyz="0 0 0"
        rpy="0 0 0" />
      <geometry>
        <mesh
          filename="package://car_urdf/meshes/Right_arm.STL" />
      </geometry>
      <material
        name="">
        <color
          rgba="0.749019607843137 0.749019607843137 0.749019607843137 1" />
      </material>
    </visual>
    <collision>
      <origin
        xyz="0 0 0"
        rpy="0 0 0" />
      <geometry>
        <mesh
          filename="package://car_urdf/meshes/Right_arm.STL" />
      </geometry>
    </collision>
  </link>
  <joint
    name="Right_arm_joint"
    type="revolute">
    <origin
      xyz="0.0010108 0.030733 -1.408E-05"
      rpy="0 0 0" />
    <parent
      link="Rigth_gear" />
    <child
      link="Right_arm" />
    <axis
      xyz="0 0 1" />
    <limit
      lower="0.0"
      upper="1.7"
      effort="0.1"
      velocity="1" />
    <!--<mimic
      joint="Left_gear_joint"
      multiplier="1"
      offset="0" />-->
  </joint>
  <link
    name="Left_Link">
    <inertial>
      <origin
        xyz="-0.00144581741485969 0.015434991461444 -0.00198005552093664"
        rpy="0 0 0" />
      <mass
        value="0.2" />
      <inertia
        ixx="1.02091108447245E-01"
        ixy="0"
        ixz="0"
        iyy="4.46360296367216E-01"
        iyz="0"
        izz="1.04423773010116E-01" />
    </inertial>
    <visual>
      <origin
        xyz="0 0 0"
        rpy="0 0 0" />
      <geometry>
        <mesh
          filename="package://car_urdf/meshes/Left_Link.STL" />
      </geometry>
      <material
        name="">
        <color
          rgba="0.749019607843137 0.749019607843137 0.749019607843137 1" />
      </material>
    </visual>
    <collision>
      <origin
        xyz="0 0 0"
        rpy="0 0 0" />
      <geometry>
        <mesh
          filename="package://car_urdf/meshes/Left_Link.STL" />
      </geometry>
    </collision>
  </link>
  <joint
    name="Left_Link_joint"
    type="revolute">
    <origin
      xyz="0.018124 0.058 0.0087484"
      rpy="0 1.5708 0" />
    <parent
      link="Wrist_pitch" />
    <child
      link="Left_Link" />
    <axis
      xyz="0 0 1" />
    <limit
      lower="0.0"
      upper="1.7"
      effort="0.1"
      velocity="1" />
    <!--<mimic
      joint="Left_gear_joint"
      multiplier="1"
      offset="0" />-->
  </joint>
  <link
    name="Rigth_Link">
    <inertial>
      <origin
        xyz="0.000194111140012471 0.0154984092987498 -0.00200289770703868"
        rpy="0 0 0" />
      <mass
        value="0.4" />
      <inertia
        ixx="1.0290168438821E-01"
        ixy="0"
        ixz="0"
        iyy="3.65286976237582E-01"
        iyz="0"
        izz="1.04423930270447E-01" />
    </inertial>
    <visual>
      <origin
        xyz="0 0 0"
        rpy="0 0 0" />
      <geometry>
        <mesh
          filename="package://car_urdf/meshes/Rigth_Link.STL" />
      </geometry>
      <material
        name="">
        <color
          rgba="0.749019607843137 0.749019607843137 0.749019607843137 1" />
      </material>
    </visual>
    <collision>
      <origin
        xyz="0 0 0"
        rpy="0 0 0" />
      <geometry>
        <mesh
          filename="package://car_urdf/meshes/Rigth_Link.STL" />
      </geometry>
    </collision>
  </link>
  <joint
    name="Rigth_Link_joint"
    type="revolute">
    <origin
      xyz="0.017984 0.058 -0.0012506"
      rpy="0 1.5708 0" />
    <parent
      link="Wrist_pitch" />
    <child
      link="Rigth_Link" />
    <axis
      xyz="0 0 1" />
    <limit
      lower="-1.7"
      upper="0.0"
      effort="0.1"
      velocity="1" />
    <!--<mimic
      joint="Left_gear_joint"
      multiplier="-1"
      offset="0" />-->
  </joint>

  <transmission name="Rueda_izquierda_del_link_trans">
	<type>transmission_interface/SimpleTransmission</type>
	<joint name="Rueda_izquierda_del_joint">
	  <hardwareInterface>hardware_interface/VelocityJointInterface</hardwareInterface>
	</joint>
	<actuator name="Rueda_izquierda_del_link_motor">
	  <hardwareInterface>hardware_interface/VelocityJointInterface</hardwareInterface>
	  <mechanicalReduction>1</mechanicalReduction>
	</actuator>
  </transmission>

  <transmission name="Rueda_derecha_del_link_trans">
	<type>transmission_interface/SimpleTransmission</type>
	  <joint name="Rueda_derecha_del_joint">
	<hardwareInterface>hardware_interface/VelocityJointInterface</hardwareInterface>
	</joint>
	<actuator name="Rueda_derecha_del_link_motor">
	  <hardwareInterface>hardware_interface/VelocityJointInterface</hardwareInterface>
	  <mechanicalReduction>1</mechanicalReduction>
	</actuator>
  </transmission>

  <transmission name="Rueda_izquierda_tras_link_trans">
	<type>transmission_interface/SimpleTransmission</type>
	<joint name="Rueda_izquierda_tras_joint">
	  <hardwareInterface>hardware_interface/VelocityJointInterface</hardwareInterface>
	</joint>
	<actuator name="Rueda_izquierda_tras_link_motor">
	  <hardwareInterface>hardware_interface/VelocityJointInterface</hardwareInterface>
	  <mechanicalReduction>1</mechanicalReduction>
	</actuator>
  </transmission>

  <transmission name="Rueda_derecha_tras_link_trans">
	<type>transmission_interface/SimpleTransmission</type>
	<joint name="Rueda_derecha_tras_joint">
	  <hardwareInterface>hardware_interface/VelocityJointInterface</hardwareInterface>
	</joint>
	<actuator name="Rueda_derecha_tras_link_motor">
	  <hardwareInterface>hardware_interface/VelocityJointInterface</hardwareInterface>
	  <mechanicalReduction>1</mechanicalReduction>
	</actuator>
  </transmission>

  <transmission name="Waist_trans">
	<type>transmission_interface/SimpleTransmission</type>
	<joint name="Waist_joint">
	<hardwareInterface>hardware_interface/PositionJointInterface</hardwareInterface>
	</joint>
	<actuator name="Waist_motor">
	<hardwareInterface>hardware_interface/PositionJointInterface</hardwareInterface>
		<mechanicalReduction>1</mechanicalReduction>
	</actuator>
  </transmission>

  <transmission name="Shoulder_trans">
	<type>transmission_interface/SimpleTransmission</type>
	<joint name="Shoulder_joint">
	<hardwareInterface>hardware_interface/PositionJointInterface</hardwareInterface>
	</joint>
	<actuator name="Shoulder_motor">
	<hardwareInterface>hardware_interface/PositionJointInterface</hardwareInterface>
		<mechanicalReduction>1</mechanicalReduction>
	</actuator>
  </transmission>

  <transmission name="Elbow_trans">
	<type>transmission_interface/SimpleTransmission</type>
	<joint name="Elbow_joint">
	<hardwareInterface>hardware_interface/PositionJointInterface</hardwareInterface>
	</joint>
	<actuator name="Elbow_motor">
	<hardwareInterface>hardware_interface/PositionJointInterface</hardwareInterface>
		<mechanicalReduction>1</mechanicalReduction>
	</actuator>
  </transmission>

  <transmission name="Wrist_Roll_trans">
	<type>transmission_interface/SimpleTransmission</type>
	<joint name="Wrist_Roll_joint">
	<hardwareInterface>hardware_interface/PositionJointInterface</hardwareInterface>
	</joint>
	<actuator name="Wrist_Roll_motor">
	<hardwareInterface>hardware_interface/PositionJointInterface</hardwareInterface>
		<mechanicalReduction>1</mechanicalReduction>
	</actuator>
  </transmission>

  <transmission name="Wrist_pitch_trans">
	<type>transmission_interface/SimpleTransmission</type>
	<joint name="Wrist_pitch_joint">
	<hardwareInterface>hardware_interface/PositionJointInterface</hardwareInterface>
	</joint>
	<actuator name="Wrist_pitch_motor">
	<hardwareInterface>hardware_interface/PositionJointInterface</hardwareInterface>
		<mechanicalReduction>1</mechanicalReduction>
	</actuator>
  </transmission>

  <transmission name="Left_gear_trans">
	<type>transmission_interface/SimpleTransmission</type>
	<joint name="Left_gear_joint">
	<hardwareInterface>hardware_interface/PositionJointInterface</hardwareInterface>
	</joint>
	<actuator name="Left_gear_motor">
	<hardwareInterface>hardware_interface/PositionJointInterface</hardwareInterface>
		<mechanicalReduction>1</mechanicalReduction>
	</actuator>
  </transmission>

  <transmission name="Left_arm_trans">
	<type>transmission_interface/SimpleTransmission</type>
	<joint name="Left_arm_joint">
	<hardwareInterface>hardware_interface/PositionJointInterface</hardwareInterface>
	</joint>
	<actuator name="Left_arm_motor">
	<hardwareInterface>hardware_interface/PositionJointInterface</hardwareInterface>
		<mechanicalReduction>1</mechanicalReduction>
	</actuator>
  </transmission>

  <transmission name="Rigth_gear_trans">
	<type>transmission_interface/SimpleTransmission</type>
	<joint name="Rigth_gear_joint">
	<hardwareInterface>hardware_interface/PositionJointInterface</hardwareInterface>
	</joint>
	<actuator name="Rigth_gear_motor">
	<hardwareInterface>hardware_interface/PositionJointInterface</hardwareInterface>
		<mechanicalReduction>1</mechanicalReduction>
	</actuator>
  </transmission>

  <transmission name="Right_arm_trans">
	<type>transmission_interface/SimpleTransmission</type>
	<joint name="Right_arm_joint">
	<hardwareInterface>hardware_interface/PositionJointInterface</hardwareInterface>
	</joint>
	<actuator name="Right_arm_motor">
		<hardwareInterface>hardware_interface/PositionJointInterface</hardwareInterface>
		<mechanicalReduction>1</mechanicalReduction>
	</actuator>
  </transmission>

  <transmission name="Left_Link_trans">
	<type>transmission_interface/SimpleTransmission</type>
	<joint name="Left_Link_joint">
	<hardwareInterface>hardware_interface/PositionJointInterface</hardwareInterface>
	</joint>
	<actuator name="Left_Link_motor">
	<hardwareInterface>hardware_interface/PositionJointInterface</hardwareInterface>
		<mechanicalReduction>1</mechanicalReduction>
	</actuator>
  </transmission>

  <transmission name="Rigth_Link_trans">
	<type>transmission_interface/SimpleTransmission</type>
	<joint name="Rigth_Link_joint">
	<hardwareInterface>hardware_interface/PositionJointInterface</hardwareInterface>
	</joint>
	<actuator name="Rigth_Link_motor">
	<hardwareInterface>hardware_interface/PositionJointInterface</hardwareInterface>
		<mechanicalReduction>1</mechanicalReduction>
	</actuator>
  </transmission>

  <gazebo>
	<plugin name="control" filename="libgazebo_ros_control.so">
		<robotNamespace>/</robotNamespace>
	</plugin>
  </gazebo>

  <!--<gazebo>
    <plugin name="gazebo_mimic_joint_plugin_1" filename="libroboticsgroup_gazebo_mimic_joint_plugin.so">
      <joint>Left_gear_joint</joint>
      <mimicJoint>Left_arm_joint</mimicJoint>
      <multiplier>-1.0</multiplier>
      <offset>0.0</offset> 
      <sensitiveness>0.0</sensitiveness>
      <maxEffort>500</maxEffort>
      <robotNamespace>/ur5</robotNamespace>
    </plugin>
    <plugin name="gazebo_mimic_joint_plugin_2" filename="libroboticsgroup_gazebo_mimic_joint_plugin.so">
      <joint>Left_gear_joint</joint>
      <mimicJoint>Rigth_gear_joint</mimicJoint>
      <multiplier>-1.0</multiplier>
      <offset>0.0</offset> 
      <sensitiveness>0.0</sensitiveness>
      <maxEffort>500</maxEffort>
      <robotNamespace>/ur5</robotNamespace>
    </plugin>
    <plugin name="gazebo_mimic_joint_plugin_3" filename="libroboticsgroup_gazebo_mimic_joint_plugin.so">
      <joint>Left_gear_joint</joint>
      <mimicJoint>Right_arm_joint</mimicJoint>
      <multiplier>1.0</multiplier>
      <offset>0.0</offset>
      <sensitiveness>0.0</sensitiveness>
      <maxEffort>500</maxEffort>
      <robotNamespace>/ur5</robotNamespace>
    </plugin>
    <plugin name="gazebo_mimic_joint_plugin_4" filename="libroboticsgroup_gazebo_mimic_joint_plugin.so">
      <joint>Left_gear_joint</joint>
      <mimicJoint>Left_Link_joint</mimicJoint>
      <multiplier>1.0</multiplier>
      <offset>0.0</offset>
      <sensitiveness>0.0</sensitiveness>
      <maxEffort>500</maxEffort>
      <robotNamespace>/ur5</robotNamespace>
    </plugin>
    <plugin name="gazebo_mimic_joint_plugin_5" filename="libroboticsgroup_gazebo_mimic_joint_plugin.so">
      <joint>Left_gear_joint</joint>
      <mimicJoint>Rigth_Link_joint</mimicJoint>
      <multiplier>-1.0</multiplier>
      <offset>0.0</offset>
      <sensitiveness>0.0</sensitiveness>
      <maxEffort>500</maxEffort>
      <robotNamespace>/ur5</robotNamespace>
    </plugin>
  </gazebo>-->

  <gazebo>
    <plugin name="gazebo_grasp_fix" filename="libgazebo_grasp_fix.so">
      <arm>
        <arm_name>gripper</arm_name>
        <palm_link>Wrist_pitch</palm_link>
        <gripper_link>Left_gear</gripper_link>
        <gripper_link>Rigth_gear</gripper_link>
        <gripper_link>Left_arm</gripper_link>
        <gripper_link>Right_arm</gripper_link>
        <gripper_link>Left_Link</gripper_link>
        <gripper_link>Rigth_Link</gripper_link>
      </arm>
      <forces_angle_tolerance>80</forces_angle_tolerance>
      <update_rate>4</update_rate>
      <grip_count_threshold>4</grip_count_threshold>
      <max_grip_count>8</max_grip_count>
      <release_tolerance>0.005</release_tolerance>
      <disable_collisions_on_attach>false</disable_collisions_on_attach>
      <contact_topic>__default_topic__</contact_topic>
    </plugin>
  </gazebo>

  <gazebo>
  	<plugin name="omni_steering" filename="libgazebo_ros_planar_move.so">
	  <commandTopic>cmd_vel</commandTopic>
	  <odometryTopic>odom</odometryTopic>
      <odometryFrame>odom</odometryFrame>  	
	  <odometryRate>50.0</odometryRate>
	  <robotBaseFrame>base_link</robotBaseFrame> 
  	  <publishTF>false</publishTF>
  	</plugin>
  </gazebo>

  <gazebo reference="Rueda_izquierda_del_link">
	<selfCollide>true</selfCollide>
 	<material>Gazebo/White</material>
	<mu1>1.0</mu1>
	<mu2>1.0</mu2>  	
	<kp>1000000.0</kp>
	<kd>100.0</kd>
	<minDepth>0.00</minDepth>
  </gazebo>

  <gazebo reference="Rueda_derecha_del_link">
	<selfCollide>true</selfCollide>
  	<material>Gazebo/Blue</material>
  	<mu1>1.0</mu1>
	<mu2>1.0</mu2>  	
	<kp>1000000.0</kp>
	<kd>100.0</kd>
	<minDepth>0.00</minDepth>
  </gazebo>

  <gazebo reference="Rueda_izquierda_tras_link">
  	<material>Gazebo/Blue</material>
  	<mu1>1.0</mu1>
	<mu2>1.0</mu2>  	
	<kp>1000000.0</kp>
	<kd>100.0</kd>
	<minDepth>0.00</minDepth>
  </gazebo>

  <gazebo reference="Rueda_derecha_tras_link">
  	<material>Gazebo/White</material>
  	<mu1>1.0</mu1>
	<mu2>1.0</mu2>  	
	<kp>1000000.0</kp>
	<kd>100.0</kd>
	<minDepth>0.00</minDepth>
  </gazebo>

  <gazebo reference="Waist">
    <material>Gazebo/Blue</material>
    <turnGravityOff>true</turnGravityOff>
  </gazebo>

  <gazebo reference="Shoulder">
    <material>Gazebo/Blue</material>
    <turnGravityOff>true</turnGravityOff>
  </gazebo>

  <gazebo reference="Elbow">
    <material>Gazebo/Blue</material>
    <turnGravityOff>true</turnGravityOff>
  </gazebo>

  <gazebo reference="Wrist_Roll">
    <material>Gazebo/Blue</material>
    <turnGravityOff>false</turnGravityOff>
  </gazebo>

  <gazebo reference="Wrist_pitch">
    <material>Gazebo/Blue</material>
    <turnGravityOff>false</turnGravityOff>
  </gazebo>

  <gazebo reference="Left_gear">
    <material>Gazebo/White</material>
    <turnGravityOff>false</turnGravityOff>
  </gazebo>

  <gazebo reference="Left_arm">
    <material>Gazebo/White</material>
    <turnGravityOff>false</turnGravityOff>
  </gazebo>

  <gazebo reference="Rigth_gear">
    <material>Gazebo/White</material>
    <turnGravityOff>false</turnGravityOff>
  </gazebo>

  <gazebo reference="Right_arm">
    <material>Gazebo/White</material>
    <turnGravityOff>false</turnGravityOff>
  </gazebo>

  <gazebo reference="Left_link">
    <material>Gazebo/White</material>
    <turnGravityOff>false</turnGravityOff>
  </gazebo>

  <gazebo reference="Rigth_link">
    <material>Gazebo/White</material>
    <turnGravityOff>false</turnGravityOff>
  </gazebo>

</robot>
